# 异步

异步（Asynchronous）指两个或两个以上的对象或事件**不同时存在或发生**（或多个相关事物的发生无需等待其前一事物的完成）。在计算机技术中，异步主要用于**网络通信**与**软件设计**中。

## 网络通信

异步通信是一种在双方或多方之间交换消息的方式。其中每个参与方各自在他们**方便或可操作的情况下**接收并处理消息，而不是在收到消息后立即进行处理。

使用这样的方式就杜绝同步的情况，比如当线程发送消息后需要等待服务器响应，为了更好利用CPU利用率在这期间做了其他操作，当服务器做出响应后，如果不采用异步的方式，当前操作和处理相应操作会冲突（这属于同步），使用异步后，可以在当前业务处理方便的情况下让出CPU处理响应消息。

## 软件设计

待补充

## Q&A

- JS是单线程的，异步不应该是多线程的吗？

  异步不一定是多线程的，但一定是非堵塞的。多线程只是异步的一种实现方式。

- 为什么需要异步编程?

  防止异步内容堵塞同步的内容。比如,你使用ajax向服务器请求数据,极端假设服务器需要10min才能返回给你数据.假设不使用异步,那么这将是堵塞的。

- JS如何实现异步的?

  JS会把异步放入`消息队列(优先级相同的情况下,先进先出)`,当同步执行完成之后,会取消息队列的内容。所以执行顺序可以理解为:同步优先、异步靠边、回调垫底。

- JS的异步有哪些?

  setTimeout()异步函数。Promise对象类型的函数,比如async/await,fetch()等。

## async/await

async修饰的函数如果不存在await,那他将是同步的.

同样,async修饰的函数返回值会被封装为Promise对象.

举例:

```js
async function test(){
    return "I am returned";
}
console.log(test()) // Promise { 'I am returned' }
```

await一般用来修饰异步(可以修饰同步,但没什么用)

当await修饰异步之后,那么await后面的操作将作为异步放到await修饰的异步的队列之后.

await修饰的异步返回值不再是Promise对象,而是Promise对象所包含的内容.

举个例子
```js
let p = new Promise(
    (resolve,reject) => {
        resolve('fulfilled');
    }
)

async function test() {
    const a = await p;
    console.log(a);
}

test();

// fulfilled
```

## setTimeout

这个异步有点特殊,他依靠时钟,不返回promise,依旧在消息队列,但优先级低于promise.

## 例子
```js
let promise = new Promise(
    (resolve, reject) => {
        // You can set resolve or reject
        // Once you set one of them, it will not change again
        resolve('Yeah, First promise is resolved! So, I can execute then() of the promise method!');
    }
)

console.log(promise);

const promiseGoOn = promise
    .then(() => {console.log(Oops);} )
    .catch(() => {console.log("Ohhh! I catch it! Last then() occurred error! It is so bad!");})
    .then(() => {
        console.log("last promise of then() or catch() is fulfilled, so I can execute.");
        return "the asynchronous method is over";
    });
    
setTimeout( () => console.log(promiseGoOn), 0)

/*
output:
Promise {
  'Yeah, First promise is resolved! So, I can execute then() of the promise method!'
}
Ohhh! I catch it! Last then() occurred error! It is so bad!
last promise of then() or catch() is fulfilled, so I can execute.
Promise { 'the asynchronous method is over' }
*/
```

